<?xml version="1.0" ?>
<!-- =================================================================================== -->
<!-- |    This document was autogenerated by xacro from vtol_simple.xacro              | -->
<!-- |    EDITING THIS FILE BY HAND IS NOT RECOMMENDED                                 | -->
<!-- =================================================================================== -->
<robot name="vtol_dron">
  <material name="silver">
    <color rgba="0.700 0.700 0.700 1.000"/>
  </material>
  <transmission name="Revolute 17_tran">
    <type>transmission_interface/SimpleTransmission</type>
    <joint name="Revolute 17">
      <hardwareInterface>hardware_interface/EffortJointInterface</hardwareInterface>
    </joint>
    <actuator name="Revolute 17_actr">
      <hardwareInterface>hardware_interface/EffortJointInterface</hardwareInterface>
      <mechanicalReduction>1</mechanicalReduction>
    </actuator>
  </transmission>
  <transmission name="Revolute 18_tran">
    <type>transmission_interface/SimpleTransmission</type>
    <joint name="Revolute 18">
      <hardwareInterface>hardware_interface/EffortJointInterface</hardwareInterface>
    </joint>
    <actuator name="Revolute 18_actr">
      <hardwareInterface>hardware_interface/EffortJointInterface</hardwareInterface>
      <mechanicalReduction>1</mechanicalReduction>
    </actuator>
  </transmission>
  <transmission name="Revolute 19_tran">
    <type>transmission_interface/SimpleTransmission</type>
    <joint name="Revolute 19">
      <hardwareInterface>hardware_interface/EffortJointInterface</hardwareInterface>
    </joint>
    <actuator name="Revolute 19_actr">
      <hardwareInterface>hardware_interface/EffortJointInterface</hardwareInterface>
      <mechanicalReduction>1</mechanicalReduction>
    </actuator>
  </transmission>
  <transmission name="Revolute 20_tran">
    <type>transmission_interface/SimpleTransmission</type>
    <joint name="Revolute 20">
      <hardwareInterface>hardware_interface/EffortJointInterface</hardwareInterface>
    </joint>
    <actuator name="Revolute 20_actr">
      <hardwareInterface>hardware_interface/EffortJointInterface</hardwareInterface>
      <mechanicalReduction>1</mechanicalReduction>
    </actuator>
  </transmission>
  <gazebo>
    <plugin filename="libgazebo_ros_control.so" name="control"/>
  </gazebo>
  <gazebo reference="base_link">
    <material>Gazebo/Silver</material>
    <mu1>0.2</mu1>
    <mu2>0.2</mu2>
    <self_collide>true</self_collide>
    <gravity>true</gravity>
  </gazebo>
  <gazebo reference="mechanism__1_1">
    <material>Gazebo/Silver</material>
    <mu1>0.2</mu1>
    <mu2>0.2</mu2>
    <self_collide>true</self_collide>
  </gazebo>
  <gazebo reference="rear_left_propeller_1">
    <material>Gazebo/Silver</material>
    <mu1>0.2</mu1>
    <mu2>0.2</mu2>
    <self_collide>true</self_collide>
  </gazebo>
  <gazebo reference="rear_right_propeller_1">
    <material>Gazebo/Silver</material>
    <mu1>0.2</mu1>
    <mu2>0.2</mu2>
    <self_collide>true</self_collide>
  </gazebo>
  <gazebo reference="front_left_propeller_1">
    <material>Gazebo/Silver</material>
    <mu1>0.2</mu1>
    <mu2>0.2</mu2>
    <self_collide>true</self_collide>
  </gazebo>
  <gazebo reference="front_right_propeller_1">
    <material>Gazebo/Silver</material>
    <mu1>0.2</mu1>
    <mu2>0.2</mu2>
    <self_collide>true</self_collide>
  </gazebo>
  <!-- ==================== BASE LINK ==================== -->
  <link name="base_link">
    <inertial>
      <!-- almost weightless -->
      <origin rpy="0 0 0" xyz="0 0 0"/>
      <mass value="0.0001"/>
      <inertia ixx="1e-6" ixy="0" ixz="0" iyy="1e-6" iyz="0" izz="1e-6"/>
    </inertial>
    <visual>
      <origin rpy="0 0 0" xyz="0 0 0"/>
      <geometry>
        <mesh filename="meshes/base_link.stl" scale="0.001 0.001 0.001"/>
      </geometry>
      <material name="silver"/>
    </visual>
    <collision>
      <origin rpy="0 0 0" xyz="0 0 0"/>
      <geometry>
        <mesh filename="meshes/base_link.stl" scale="0.001 0.001 0.001"/>
      </geometry>
    </collision>
  </link>
  <!-- ==================== MECHANISM ==================== -->
  <link name="mechanism__1_1">
    <inertial>
      <!-- negligible mass -->
      <origin rpy="0 0 0" xyz="0 0 0"/>
      <mass value="0.0001"/>
      <inertia ixx="1e-6" ixy="0" ixz="0" iyy="1e-6" iyz="0" izz="1e-6"/>
    </inertial>
    <visual>
      <origin rpy="0 0 0" xyz="0.014058 0.00682 -0.047465"/>
      <geometry>
        <mesh filename="meshes/mechanism__1_1.stl" scale="0.001 0.001 0.001"/>
      </geometry>
      <material name="silver"/>
    </visual>
    <collision>
      <origin rpy="0 0 0" xyz="0.014058 0.00682 -0.047465"/>
      <geometry>
        <mesh filename="meshes/mechanism__1_1.stl" scale="0.001 0.001 0.001"/>
      </geometry>
    </collision>
  </link>
  <!-- ==================== PROPELLER LINKS ==================== -->
  <!-- Each propeller has realistic mass (0.75 kg) and simple inertia -->
  <link name="rear_left_propeller_1">
    <inertial>
      <origin rpy="0 0 0" xyz="0 0 0"/>
      <mass value="0.75"/>
      <inertia ixx="0.001" ixy="0" ixz="0" iyy="0.001" iyz="0" izz="0.002"/>
    </inertial>
    <visual>
      <origin rpy="0 0 0" xyz="0.467618 -0.492756 -0.202098"/>
      <geometry>
        <mesh filename="meshes/rear_left_propeller_1.stl" scale="0.001 0.001 0.001"/>
      </geometry>
      <material name="silver"/>
    </visual>
    <collision>
      <origin rpy="0 0 0" xyz="0.467618 -0.492756 -0.202098"/>
      <geometry>
        <mesh filename="meshes/rear_left_propeller_1.stl" scale="0.001 0.001 0.001"/>
      </geometry>
    </collision>
  </link>
  <link name="rear_right_propeller_1">
    <inertial>
      <origin rpy="0 0 0" xyz="0 0 0"/>
      <mass value="0.75"/>
      <inertia ixx="0.001" ixy="0" ixz="0" iyy="0.001" iyz="0" izz="0.002"/>
    </inertial>
    <visual>
      <origin rpy="0 0 0" xyz="0.467618 0.507244 -0.202098"/>
      <geometry>
        <mesh filename="meshes/rear_right_propeller_1.stl" scale="0.001 0.001 0.001"/>
      </geometry>
      <material name="silver"/>
    </visual>
    <collision>
      <origin rpy="0 0 0" xyz="0.467618 0.507244 -0.202098"/>
      <geometry>
        <mesh filename="meshes/rear_right_propeller_1.stl" scale="0.001 0.001 0.001"/>
      </geometry>
    </collision>
  </link>
  <link name="front_left_propeller_1">
    <inertial>
      <origin rpy="0 0 0" xyz="0 0 0"/>
      <mass value="0.75"/>
      <inertia ixx="0.001" ixy="0" ixz="0" iyy="0.001" iyz="0" izz="0.002"/>
    </inertial>
    <visual>
      <origin rpy="0 0 0" xyz="-0.582382 -0.492756 -0.202098"/>
      <geometry>
        <mesh filename="meshes/front_left_propeller_1.stl" scale="0.001 0.001 0.001"/>
      </geometry>
      <material name="silver"/>
    </visual>
    <collision>
      <origin rpy="0 0 0" xyz="-0.582382 -0.492756 -0.202098"/>
      <geometry>
        <mesh filename="meshes/front_left_propeller_1.stl" scale="0.001 0.001 0.001"/>
      </geometry>
    </collision>
  </link>
  <link name="front_right_propeller_1">
    <inertial>
      <origin rpy="0 0 0" xyz="0 0 0"/>
      <mass value="0.75"/>
      <inertia ixx="0.001" ixy="0" ixz="0" iyy="0.001" iyz="0" izz="0.002"/>
    </inertial>
    <visual>
      <origin rpy="0 0 0" xyz="-0.582382 0.507244 -0.202098"/>
      <geometry>
        <mesh filename="meshes/front_right_propeller_1.stl" scale="0.001 0.001 0.001"/>
      </geometry>
      <material name="silver"/>
    </visual>
    <collision>
      <origin rpy="0 0 0" xyz="-0.582382 0.507244 -0.202098"/>
      <geometry>
        <mesh filename="meshes/front_right_propeller_1.stl" scale="0.001 0.001 0.001"/>
      </geometry>
    </collision>
  </link>
  <!-- ==================== JOINTS ==================== -->
  <joint name="Rigid_16" type="fixed">
    <origin rpy="0 0 0" xyz="-0.014058 -0.00682 0.047465"/>
    <parent link="base_link"/>
    <child link="mechanism__1_1"/>
  </joint>
  <joint name="Revolute_17" type="continuous">
    <origin rpy="0 0 0" xyz="-0.467618 0.492756 0.202098"/>
    <parent link="base_link"/>
    <child link="rear_left_propeller_1"/>
    <axis xyz="0 0 1"/>
  </joint>
  <joint name="Revolute_18" type="continuous">
    <origin rpy="0 0 0" xyz="-0.467618 -0.507244 0.202098"/>
    <parent link="base_link"/>
    <child link="rear_right_propeller_1"/>
    <axis xyz="0 0 1"/>
  </joint>
  <joint name="Revolute_19" type="continuous">
    <origin rpy="0 0 0" xyz="0.582382 0.492756 0.202098"/>
    <parent link="base_link"/>
    <child link="front_left_propeller_1"/>
    <axis xyz="0 0 1"/>
  </joint>
  <joint name="Revolute_20" type="continuous">
    <origin rpy="0 0 0" xyz="0.582382 -0.507244 0.202098"/>
    <parent link="base_link"/>
    <child link="front_right_propeller_1"/>
    <axis xyz="0 0 1"/>
  </joint>
</robot>
