<?xml version="1.0" ?>
<robot name="vtol_dron" xmlns:xacro="http://www.ros.org/wiki/xacro">

<xacro:include filename="$(find vtol_dron_description)/urdf/materials.xacro" />
<xacro:include filename="$(find vtol_dron_description)/urdf/vtol_dron.trans" />
<xacro:include filename="$(find vtol_dron_description)/urdf/vtol_dron.gazebo" />
<link name="base_link">
  <inertial>
    <origin xyz="0 0 0 " rpy="0 0 0"/>
    <mass value="0.0001"/>
    <inertia ixx="1e-6" iyy="1e-6" izz="1e-6" ixy="0.0" iyz="0.0" ixz="0.0"/>
  </inertial>
  <visual>
    <origin xyz="0 0 0" rpy="0 0 0"/>
    <geometry>
      <mesh filename="file://$(find vtol_dron_description)/meshes/base_link.stl" scale="0.001 0.001 0.001"/>
    </geometry>
    <material name="silver"/>
  </visual>
  <collision>
    <origin xyz="0 0 0" rpy="0 0 0"/>
    <geometry>
      <mesh filename="file://$(find vtol_dron_description)/meshes/base_link.stl" scale="0.001 0.001 0.001"/>
    </geometry>
  </collision>
</link>

<link name="mechanism__1_1">
  <inertial>
    <origin xyz="0 0 0" rpy="0 0 0"/>
    <mass value="0.0001"/>
    <inertia ixx="1e-6" iyy="1e-6" izz="1e-6" ixy="0.0" iyz="0.0" ixz="0.0"/>
  </inertial>
  <visual>
    <origin xyz="0.014058 0.00682 -0.047465" rpy="0 0 0"/>
    <geometry>
      <mesh filename="file://$(find vtol_dron_description)/meshes/mechanism__1_1.stl" scale="0.001 0.001 0.001"/>
    </geometry>
    <material name="silver"/>
  </visual>
  <collision>
    <origin xyz="0.014058 0.00682 -0.047465" rpy="0 0 0"/>
    <geometry>
      <mesh filename="file://$(find vtol_dron_description)/meshes/mechanism__1_1.stl" scale="0.001 0.001 0.001"/>
    </geometry>
  </collision>
</link>

<link name="rear_left_propeller_1">
  <inertial>
    <origin xyz="0.0005767734552350468 0.00016465964142459155 0.0017514040767991068" rpy="0 0 0"/>
    <mass value="0.27016438943444754"/>
    <inertia ixx="0.001345" iyy="0.002032" izz="0.003375" ixy="-0.001623" iyz="0.0" ixz="-0.0"/>
  </inertial>
  <visual>
    <origin xyz="0.467618 -0.492756 -0.202098" rpy="0 0 0"/>
    <geometry>
      <mesh filename="file://$(find vtol_dron_description)/meshes/rear_left_propeller_1.stl" scale="0.001 0.001 0.001"/>
    </geometry>
    <material name="silver"/>
  </visual>
  <collision>
    <origin xyz="0.467618 -0.492756 -0.202098" rpy="0 0 0"/>
    <geometry>
      <mesh filename="file://$(find vtol_dron_description)/meshes/rear_left_propeller_1.stl" scale="0.001 0.001 0.001"/>
    </geometry>
  </collision>
</link>

<link name="rear_right_propeller_1">
  <inertial>
    <origin xyz="-0.0003138715998030617 -0.0021736513155853343 0.002539772225924969" rpy="0 0 0"/>
    <mass value="0.27120099509459644"/>
    <inertia ixx="3.2e-05" iyy="0.003334" izz="0.003365" ixy="9.8e-05" iyz="-1e-06" ixz="2e-05"/>
  </inertial>
  <visual>
    <origin xyz="0.467618 0.507244 -0.202098" rpy="0 0 0"/>
    <geometry>
      <mesh filename="file://$(find vtol_dron_description)/meshes/rear_right_propeller_1.stl" scale="0.001 0.001 0.001"/>
    </geometry>
    <material name="silver"/>
  </visual>
  <collision>
    <origin xyz="0.467618 0.507244 -0.202098" rpy="0 0 0"/>
    <geometry>
      <mesh filename="file://$(find vtol_dron_description)/meshes/rear_right_propeller_1.stl" scale="0.001 0.001 0.001"/>
    </geometry>
  </collision>
</link>

<link name="front_left_propeller_1">
  <inertial>
    <origin xyz="-0.0016254362001142386 -0.0014766095341569585 0.002539772507994975" rpy="0 0 0"/>
    <mass value="0.27120093783510885"/>
    <inertia ixx="0.001466" iyy="0.0019" izz="0.003365" ixy="0.00164" iyz="-1.3e-05" ixz="1.5e-05"/>
  </inertial>
  <visual>
    <origin xyz="-0.582382 -0.492756 -0.202098" rpy="0 0 0"/>
    <geometry>
      <mesh filename="file://$(find vtol_dron_description)/meshes/front_left_propeller_1.stl" scale="0.001 0.001 0.001"/>
    </geometry>
    <material name="silver"/>
  </visual>
  <collision>
    <origin xyz="-0.582382 -0.492756 -0.202098" rpy="0 0 0"/>
    <geometry>
      <mesh filename="file://$(find vtol_dron_description)/meshes/front_left_propeller_1.stl" scale="0.001 0.001 0.001"/>
    </geometry>
  </collision>
</link>

<link name="front_right_propeller_1">
  <inertial>
    <origin xyz="0.0005550320306569878 -0.00022807279910386224 0.0017514040767967753" rpy="0 0 0"/>
    <mass value="0.27016438943445115"/>
    <inertia ixx="2.9e-05" iyy="0.003347" izz="0.003375" ixy="-4.3e-05" iyz="0.0" ixz="-0.0"/>
  </inertial>
  <visual>
    <origin xyz="-0.582382 0.507244 -0.202098" rpy="0 0 0"/>
    <geometry>
      <mesh filename="file://$(find vtol_dron_description)/meshes/front_right_propeller_1.stl" scale="0.001 0.001 0.001"/>
    </geometry>
    <material name="silver"/>
  </visual>
  <collision>
    <origin xyz="-0.582382 0.507244 -0.202098" rpy="0 0 0"/>
    <geometry>
      <mesh filename="file://$(find vtol_dron_description)/meshes/front_right_propeller_1.stl" scale="0.001 0.001 0.001"/>
    </geometry>
  </collision>
</link>

<joint name="Rigid 16" type="fixed">
  <origin xyz="-0.014058 -0.00682 0.047465" rpy="0 0 0"/>
  <parent link="base_link"/>
  <child link="mechanism__1_1"/>
</joint>

<joint name="Revolute 17" type="continuous">
  <origin xyz="-0.467618 0.492756 0.202098" rpy="0 0 0"/>
  <parent link="base_link"/>
  <child link="rear_left_propeller_1"/>
  <axis xyz="-0.0 0.0 1.0"/>
</joint>

<joint name="Revolute 18" type="continuous">
  <origin xyz="-0.467618 -0.507244 0.202098" rpy="0 0 0"/>
  <parent link="base_link"/>
  <child link="rear_right_propeller_1"/>
  <axis xyz="-0.0 0.0 1.0"/>
</joint>

<joint name="Revolute 19" type="continuous">
  <origin xyz="0.582382 0.492756 0.202098" rpy="0 0 0"/>
  <parent link="base_link"/>
  <child link="front_left_propeller_1"/>
  <axis xyz="-0.0 0.0 1.0"/>
</joint>

<joint name="Revolute 20" type="continuous">
  <origin xyz="0.582382 -0.507244 0.202098" rpy="0 0 0"/>
  <parent link="base_link"/>
  <child link="front_right_propeller_1"/>
  <axis xyz="-0.0 0.0 1.0"/>
</joint>

</robot>
