<?xml version="1.0" ?>
<!-- =================================================================================== -->
<!-- |    This document was autogenerated by xacro from vtol_dron.xacro                | -->
<!-- |    EDITING THIS FILE BY HAND IS NOT RECOMMENDED                                 | -->
<!-- =================================================================================== -->
<robot name="vtol_dron">
  <material name="silver">
    <color rgba="0.700 0.700 0.700 1.000"/>
  </material>
  <transmission name="Revolute 17_tran">
    <type>transmission_interface/SimpleTransmission</type>
    <joint name="Revolute 17">
      <hardwareInterface>hardware_interface/EffortJointInterface</hardwareInterface>
    </joint>
    <actuator name="Revolute 17_actr">
      <hardwareInterface>hardware_interface/EffortJointInterface</hardwareInterface>
      <mechanicalReduction>1</mechanicalReduction>
    </actuator>
  </transmission>
  <transmission name="Revolute 18_tran">
    <type>transmission_interface/SimpleTransmission</type>
    <joint name="Revolute 18">
      <hardwareInterface>hardware_interface/EffortJointInterface</hardwareInterface>
    </joint>
    <actuator name="Revolute 18_actr">
      <hardwareInterface>hardware_interface/EffortJointInterface</hardwareInterface>
      <mechanicalReduction>1</mechanicalReduction>
    </actuator>
  </transmission>
  <transmission name="Revolute 19_tran">
    <type>transmission_interface/SimpleTransmission</type>
    <joint name="Revolute 19">
      <hardwareInterface>hardware_interface/EffortJointInterface</hardwareInterface>
    </joint>
    <actuator name="Revolute 19_actr">
      <hardwareInterface>hardware_interface/EffortJointInterface</hardwareInterface>
      <mechanicalReduction>1</mechanicalReduction>
    </actuator>
  </transmission>
  <transmission name="Revolute 20_tran">
    <type>transmission_interface/SimpleTransmission</type>
    <joint name="Revolute 20">
      <hardwareInterface>hardware_interface/EffortJointInterface</hardwareInterface>
    </joint>
    <actuator name="Revolute 20_actr">
      <hardwareInterface>hardware_interface/EffortJointInterface</hardwareInterface>
      <mechanicalReduction>1</mechanicalReduction>
    </actuator>
  </transmission>
  <gazebo>
    <plugin filename="libgazebo_ros_control.so" name="control"/>
  </gazebo>
  <gazebo reference="base_link">
    <material>Gazebo/Silver</material>
    <mu1>0.2</mu1>
    <mu2>0.2</mu2>
    <self_collide>true</self_collide>
    <gravity>true</gravity>
  </gazebo>
  <gazebo reference="mechanism__1_1">
    <material>Gazebo/Silver</material>
    <mu1>0.2</mu1>
    <mu2>0.2</mu2>
    <self_collide>true</self_collide>
  </gazebo>
  <gazebo reference="rear_left_propeller_1_1">
    <material>Gazebo/Silver</material>
    <mu1>0.2</mu1>
    <mu2>0.2</mu2>
    <self_collide>true</self_collide>
  </gazebo>
  <gazebo reference="rear_right__1_1">
    <material>Gazebo/Silver</material>
    <mu1>0.2</mu1>
    <mu2>0.2</mu2>
    <self_collide>true</self_collide>
  </gazebo>
  <gazebo reference="front_left_propeller_1_1">
    <material>Gazebo/Silver</material>
    <mu1>0.2</mu1>
    <mu2>0.2</mu2>
    <self_collide>true</self_collide>
  </gazebo>
  <gazebo reference="right_front_propeller_1_1">
    <material>Gazebo/Silver</material>
    <mu1>0.2</mu1>
    <mu2>0.2</mu2>
    <self_collide>true</self_collide>
  </gazebo>
  <link name="base_link">
    <inertial>
      <origin rpy="0 0 0" xyz="0.05537682059238933 -0.9038990786030477 0.148130029924416"/>
      <mass value="514.4421916299952"/>
      <inertia ixx="61.122388" ixy="0.028098" ixz="-0.006512" iyy="122.498985" iyz="4.353056" izz="178.33007"/>
    </inertial>
    <visual>
      <origin rpy="0 0 0" xyz="0 0 0"/>
      <geometry>
        <mesh filename="file:///home/qasob/swarm_robots_ws/install/vtol_dron_description/share/vtol_dron_description/meshes/base_link.stl" scale="0.001 0.001 0.001"/>
      </geometry>
      <material name="silver"/>
    </visual>
    <collision>
      <origin rpy="0 0 0" xyz="0 0 0"/>
      <geometry>
        <mesh filename="file:///home/qasob/swarm_robots_ws/install/vtol_dron_description/share/vtol_dron_description/meshes/base_link.stl" scale="0.001 0.001 0.001"/>
      </geometry>
    </collision>
  </link>
  <link name="mechanism__1_1">
    <inertial>
      <origin rpy="0 0 0" xyz="5.351954205646409e-05 0.10289173100323268 -0.014246567223588108"/>
      <mass value="5.138700583953305"/>
      <inertia ixx="0.032521" ixy="1.7e-05" ixz="-5e-06" iyy="0.034905" iyz="0.000374" izz="0.055253"/>
    </inertial>
    <visual>
      <origin rpy="0 0 0" xyz="-0.054972 0.875262 -0.047465"/>
      <geometry>
        <mesh filename="file:///home/qasob/swarm_robots_ws/install/vtol_dron_description/share/vtol_dron_description/meshes/mechanism__1_1.stl" scale="0.001 0.001 0.001"/>
      </geometry>
      <material name="silver"/>
    </visual>
    <collision>
      <origin rpy="0 0 0" xyz="-0.054972 0.875262 -0.047465"/>
      <geometry>
        <mesh filename="file:///home/qasob/swarm_robots_ws/install/vtol_dron_description/share/vtol_dron_description/meshes/mechanism__1_1.stl" scale="0.001 0.001 0.001"/>
      </geometry>
    </collision>
  </link>
  <link name="rear_left_propeller_1_1">
    <inertial>
      <origin rpy="0 0 0" xyz="-0.00011439029518178767 0.0005887794827541537 0.0017514040767982464"/>
      <mass value="0.27016438943444754"/>
      <inertia ixx="0.002308" ixy="0.001539" ixz="-0.0" iyy="0.001068" iyz="-0.0" izz="0.003375"/>
    </inertial>
    <visual>
      <origin rpy="0 0 0" xyz="0.444604 1.328822 -0.202098"/>
      <geometry>
        <mesh filename="file:///home/qasob/swarm_robots_ws/install/vtol_dron_description/share/vtol_dron_description/meshes/rear_left_propeller_1_1.stl" scale="0.001 0.001 0.001"/>
      </geometry>
      <material name="silver"/>
    </visual>
    <collision>
      <origin rpy="0 0 0" xyz="0.444604 1.328822 -0.202098"/>
      <geometry>
        <mesh filename="file:///home/qasob/swarm_robots_ws/install/vtol_dron_description/share/vtol_dron_description/meshes/rear_left_propeller_1_1.stl" scale="0.001 0.001 0.001"/>
      </geometry>
    </collision>
  </link>
  <link name="rear_right__1_1">
    <inertial>
      <origin rpy="0 0 0" xyz="0.002173039669780219 -0.0003140596028199383 0.0025397722259243027"/>
      <mass value="0.27120099509459644"/>
      <inertia ixx="0.003334" ixy="-9.8e-05" ixz="1e-06" iyy="3.2e-05" iyz="2e-05" izz="0.003365"/>
    </inertial>
    <visual>
      <origin rpy="0 0 0" xyz="-0.555396 1.328822 -0.202098"/>
      <geometry>
        <mesh filename="file:///home/qasob/swarm_robots_ws/install/vtol_dron_description/share/vtol_dron_description/meshes/rear_right__1_1.stl" scale="0.001 0.001 0.001"/>
      </geometry>
      <material name="silver"/>
    </visual>
    <collision>
      <origin rpy="0 0 0" xyz="-0.555396 1.328822 -0.202098"/>
      <geometry>
        <mesh filename="file:///home/qasob/swarm_robots_ws/install/vtol_dron_description/share/vtol_dron_description/meshes/rear_right__1_1.stl" scale="0.001 0.001 0.001"/>
      </geometry>
    </collision>
  </link>
  <link name="front_left_propeller_1_1">
    <inertial>
      <origin rpy="0 0 0" xyz="0.0014759978883546188 -0.0016256242031302826 0.0025397725079946976"/>
      <mass value="0.27120093783510885"/>
      <inertia ixx="0.0019" ixy="-0.00164" ixz="1.3e-05" iyy="0.001466" iyz="1.5e-05" izz="0.003365"/>
    </inertial>
    <visual>
      <origin rpy="0 0 0" xyz="0.444604 0.278822 -0.202098"/>
      <geometry>
        <mesh filename="file:///home/qasob/swarm_robots_ws/install/vtol_dron_description/share/vtol_dron_description/meshes/front_left_propeller_1_1.stl" scale="0.001 0.001 0.001"/>
      </geometry>
      <material name="silver"/>
    </visual>
    <collision>
      <origin rpy="0 0 0" xyz="0.444604 0.278822 -0.202098"/>
      <geometry>
        <mesh filename="file:///home/qasob/swarm_robots_ws/install/vtol_dron_description/share/vtol_dron_description/meshes/front_left_propeller_1_1.stl" scale="0.001 0.001 0.001"/>
      </geometry>
    </collision>
  </link>
  <link name="right_front_propeller_1_1">
    <inertial>
      <origin rpy="0 0 0" xyz="0.0002274611533005233 0.0005548440276391675 0.0017514040767967476"/>
      <mass value="0.27016438943445115"/>
      <inertia ixx="0.003347" ixy="4.3e-05" ixz="-0.0" iyy="2.9e-05" iyz="-0.0" izz="0.003375"/>
    </inertial>
    <visual>
      <origin rpy="0 0 0" xyz="-0.555396 0.278822 -0.202098"/>
      <geometry>
        <mesh filename="file:///home/qasob/swarm_robots_ws/install/vtol_dron_description/share/vtol_dron_description/meshes/right_front_propeller_1_1.stl" scale="0.001 0.001 0.001"/>
      </geometry>
      <material name="silver"/>
    </visual>
    <collision>
      <origin rpy="0 0 0" xyz="-0.555396 0.278822 -0.202098"/>
      <geometry>
        <mesh filename="file:///home/qasob/swarm_robots_ws/install/vtol_dron_description/share/vtol_dron_description/meshes/right_front_propeller_1_1.stl" scale="0.001 0.001 0.001"/>
      </geometry>
    </collision>
  </link>
  <joint name="Rigid 16" type="fixed">
    <origin rpy="0 0 0" xyz="0.054972 -0.875262 0.047465"/>
    <parent link="base_link"/>
    <child link="mechanism__1_1"/>
  </joint>
  <joint name="Revolute 17" type="continuous">
    <origin rpy="0 0 0" xyz="-0.444604 -1.328822 0.202098"/>
    <parent link="base_link"/>
    <child link="rear_left_propeller_1_1"/>
    <axis xyz="-0.0 -0.0 1.0"/>
  </joint>
  <joint name="Revolute 18" type="continuous">
    <origin rpy="0 0 0" xyz="0.555396 -1.328822 0.202098"/>
    <parent link="base_link"/>
    <child link="rear_right__1_1"/>
    <axis xyz="-0.0 -0.0 1.0"/>
  </joint>
  <joint name="Revolute 19" type="continuous">
    <origin rpy="0 0 0" xyz="-0.444604 -0.278822 0.202098"/>
    <parent link="base_link"/>
    <child link="front_left_propeller_1_1"/>
    <axis xyz="-0.0 -0.0 1.0"/>
  </joint>
  <joint name="Revolute 20" type="continuous">
    <origin rpy="0 0 0" xyz="0.555396 -0.278822 0.202098"/>
    <parent link="base_link"/>
    <child link="right_front_propeller_1_1"/>
    <axis xyz="-0.0 -0.0 1.0"/>
  </joint>
</robot>
